Workbook

Sheet DCF
B2: Prepared by Marcel CHANARD | D2: Discounted Cash Flow (DCF) Valuation – LVMH | H2: 03/31/2026
B4: All figures in € millions unless stated otherwise
B6: Assumptions | D6: Rate
B7: Revenue Growth | D7: 4,5% → 5,0% → 5,5% → 5,0% → 4,5%
B8: EBIT Margin | D8: =Financials!C38 -> 0.23849956
B9: Tax Rate | D9: =Financials!C41 -> 0.29166667
B10: D&A % of Revenue | D10: =Financials!C44 -> 0.070241626
B11: Capex % of Revenue | D11: =Financials!C46 -> 0.069555915
B12: NWC % of Revenue | D12: =Financials!C48 -> 0.027662115
B13: WACC | D13: =Financials!G35 -> 0.077147396
B14: Terminal Growth | D14: =Financials!G45 -> 0.025
B18: Operating Forecast
D20: 2025A | E20: 2026E | F20: 2027E | G20: 2028E | H20: 2029E | I20: 2030E
B21: Revenue | D21: =Financials!E7 -> 80807 | E21: =D21*(1+E22) -> 84443.315 | F21: =E21*(1+F22) -> 88665.481 | G21: =F21*(1+G22) -> 93542.082 | H21: =G21*(1+H22) -> 98219.186 | I21: =H21*(1+I22) -> 102639.05
B22: Revenue Growth % | D22: ="" | E22: =Financials!C23 -> 0.045 | F22: =Financials!C24 -> 0.05 | G22: =Financials!C25 -> 0.055 | H22: =Financials!C26 -> 0.05 | I22: =Financials!C27 -> 0.045
B24: EBIT Margin | D24: =Financials!C37 -> 0.21972106 | E24: =$D$8 -> 0.23849956 | F24: =$D$8 -> 0.23849956 | G24: =$D$8 -> 0.23849956 | H24: =$D$8 -> 0.23849956 | I24: =$D$8 -> 0.23849956
B25: EBIT | D25: =Financials!E8 -> 17755 | E25: =E21*E24 -> 20139.694 | F25: =F21*F24 -> 21146.679 | G25: =G21*G24 -> 22309.746 | H25: =H21*H24 -> 23425.233 | I25: =I21*I24 -> 24479.369
B27: Taxes | D27: =D25*Financials!E15 -> 5823.64 | E27: =E25*$D$9 -> 5874.0774 | F27: =F25*$D$9 -> 6167.7812 | G27: =G25*$D$9 -> 6507.0092 | H27: =H25*$D$9 -> 6832.3597 | I27: =I25*$D$9 -> 7139.8159
B28: NOPAT | D28: =D25-D27 -> 11931.36 | E28: =E25-E27 -> 14265.616 | F28: =F25-F27 -> 14978.897 | G28: =G25-G27 -> 15802.737 | H28: =H25-H27 -> 16592.873 | I28: =I25-I27 -> 17339.553
B29: D&A | D29: =Financials!E10 -> 6088 | E29: =E21*$D$10 -> 5931.4358 | F29: =F21*$D$10 -> 6228.0076 | G29: =G21*$D$10 -> 6570.548 | H29: =H21*$D$10 -> 6899.0754 | I29: =I21*$D$10 -> 7209.5338
B30: Capex | D30: =Financials!E11 -> 4570 | E30: =E21*$D$11 -> 5873.532 | F30: =F21*$D$11 -> 6167.2086 | G30: =G21*$D$11 -> 6506.4051 | H30: =H21*$D$11 -> 6831.7254 | I30: =I21*$D$11 -> 7139.153
B31: Change in NWC | D31: =Financials!E12 -> 576 | E31: =E21*$D$12 -> 2335.8807 | F31: =F21*$D$12 -> 2452.6747 | G31: =G21*$D$12 -> 2587.5718 | H31: =H21*$D$12 -> 2716.9504 | I31: =I21*$D$12 -> 2839.2132
B35: Free Cash Flow
D37: 2025A | E37: 2026E | F37: 2027E | G37: 2028E | H37: 2029E | I37: 2030E
B38: Free Cash Flow | D38: =D28+D29-D30-D31 -> 12873.36 | E38: =E28+E29-E30-E31 -> 11987.64 | F38: =F28+F29-F30-F31 -> 12587.021 | G38: =G28+G29-G30-G31 -> 13279.308 | H38: =H28+H29-H30-H31 -> 13943.273 | I38: =I28+I29-I30-I31 -> 14570.72
B39: (NOPAT + D&A - CAPEX - Change in NWC)
B43: DCF Valuation
D45: 2025A | E45: 2026E | F45: 2027E | G45: 2028E | H45: 2029E | I45: 2030E
B46: Discount Factor | E46: =1/(1+$D$13)^1 -> 0.92837805 | F46: =1/(1+$D$13)^2 -> 0.8618858 | G46: =1/(1+$D$13)^3 -> 0.80015586 | H46: =1/(1+$D$13)^4 -> 0.74284714 | I46: =1/(1+$D$13)^5 -> 0.68964298
B47: PV of FCF | E47: =E38*E46 -> 11129.061 | F47: =F38*F46 -> 10848.575 | G47: =G38*G46 -> 10625.516 | H47: =H38*H46 -> 10357.721 | I47: =I38*I46 -> 10048.595
B50: Terminal Value | C50: =I38*(1+$D$14)/($D$13-$D$14) -> 286399.5
B51: PV Terminal Value | C51: =C50*I46 -> 197513.41
B53: Enterprise Value | C53: =SUM(E47:I47)+C51 -> 250522.87
B54: Less Net Debt | C54: =Financials!E13 -> 6857
B55: ="= Equity Value" -> = Equity Value | C55: =C53-C54 -> 243665.87
B57: Price per Share | C57: =(C53-C54)/Financials!E14 -> 491.26184
B61: Bridge to Equity Value
B63: =B53 -> Enterprise Value | C63: =C53 -> 250522.87
B64: =B54 -> Less Net Debt | C64: =C54 -> 6857
B65: =B55 -> = Equity Value | C65: =C55 -> 243665.87
...

Sheet Financials
B2: Prepared by Marcel CHANARD | D2: Financials + Calculations
B4: All figures in € millions unless stated otherwise
C6: 2023A | D6: 2024A | E6: 2025A
B7: Revenue | C7: 86153 | D7: 84683 | E7: 80807
B8: EBIT (Recurring) | C8: 22802 | D8: 19571 | E8: 17755
B9: Net Income | C9: 15174 | D9: 12550 | E9: 10878
B10: D&A | C10: 5521 | D10: 6038 | E10: 6088
B11: Capex | C11: 7478 | D11: 5531 | E11: 4570
B12: Change in NWC | C12: 4577 | D12: 1925 | E12: 576
B13: Net Financial Debt | C13: 10746 | D13: 9228 | E13: 6857
B14: Shares Outstanding | C14: 502 | D14: 498 | E14: 496
B15: Effective Tax Rate | C15: 0.262 | D15: 0.285 | E15: 0.328
D19: Calculations & Explanations
B21: Revenue Growth | F21: WACC Calculation (March 2026)
B22: Year-Specific Growth Rates (Tapered) | F22: Component | G22: Value | H22: Source
B23: 2026E: | C23: 0.045 | F23: Risk-Free Rate | G23: 0.032 | H23: Banque de France
B24: 2027E: | C24: 0.05 | F24: Beta | G24: 0.9 | H24: Bloomberg / Damodaran
B25: 2028E: | C25: 0.055 | F25: Equity Risk Premium | G25: 0.052 | H25: Damodaran, Jan 2025
B26: 2029E: | C26: 0.05 | F26: Cost of Equity | G26: =G23+G24*G25 -> 0.0788
B27: 2030E: | C27: 0.045 | F27: Cost of Debt | G27: 0.032 | H27: LVMH 2024 Annual Report
F28: Tax rate | G28: =AVERAGE(C15:E15) -> 0.29166667 | H28: Normalized
B29: Actual "Growth Rate" | F29: After-tax Cost of Debt | G29: =G27*(1-G28) -> 0.022666667
B30: 2023A: | C30: =D7/C7-1 -> -0.017062668 | F30: Share price | G30: 455.75 | H30: Yahoo Finance, MC.PA close, March 27, 2016
B31: 2024A: | C31: =E7/D7-1 -> -0.045770698 | F31: Market Cap | G31: =G30*E14 -> 226052
B32: Average growth: | C32: =AVERAGE(C30:C31) -> -0.031416683 | F32: Net Debt | G32: =E13 -> 6857 | H32: LVMH 2024 Annual Report
F33: E/V | G33: =G31/(G31+G32) -> 0.97055932
B34: EBIT Historical Margin | F34: D/V | G34: =G32/(G31+G32) -> 0.029440683
B35: 2023 | C35: =C8/C7 -> 0.26466867 | F35: WACC | G35: =(G33*G26)+(G34*G29) -> 0.077147396
B36: 2024 | C36: =D8/D7 -> 0.23110896
B37: 2025 | C37: =E8/E7 -> 0.21972106 | F37: Terminal Growth Support (March 2026)
B38: Average: | C38: =AVERAGE(C35:C37) -> 0.23849956
F39: Europe Revenue Weight | G39: 0.25 | I39: Europe Long-run GDP | J39: 0.015
B40: Tax rate | F40: US Revenue Weight | G40: 0.25 | I40: US Long-run GDP | J40: 0.02
B41: Average tax rate: | C41: =AVERAGE(C15:E15) -> 0.29166667 | F41: Asia Revenue Weight | G41: 0.3 | I41: Asia Long-run GDP | J41: 0.04
F42: Other Revenue Weight | G42: =1-G39-G40-G41 -> 0.2 | I42: Other Long-run GDP | J42: 0.01
B43: % of Revenue
B44: D&A / Revenue (3Y avg.) | C44: =AVERAGE(C10/C7,D10/D7,E10/E7) -> 0.070241626 | F44: Implied Terminal Growth | G44: =(G39*J39)+(G40*J40)+(G41*J41)+(G42*J42) -> 0.02275
F45: Normalized Terminal Growth | G45: 0.025 | H45: Selected terminal growth
B46: Capex / Revenue (3Y avg.) | C46: =AVERAGE(C11/C7,D11/D7,E11/E7) -> 0.069555915
B48: Change in NWC / Revenue (3Y avg.) | C48: =AVERAGE(C12/C7,D12/D7,E12/E7) -> 0.027662115
